Workbook
Name ___DAT1: #REF!
Name ___DAT1: #REF!
Name ___DAT1: #REF!
Name ___DAT10: #REF!
Name ___DAT10: #REF!
Name ___DAT11: #REF!
Name ___DAT11: #REF!
Name ___DAT12: #REF!
Name ___DAT12: #REF!
Name ___DAT13: #REF!
Name ___DAT13: #REF!
Name ___DAT2: #REF!
Name ___DAT2: #REF!
Name ___DAT3: #REF!
Name ___DAT3: #REF!
Name ___DAT4: #REF!
Name ___DAT4: #REF!
Name ___DAT5: #REF!
Name ___DAT5: #REF!
Name ___DAT6: #REF!
Name ___DAT6: #REF!
Name ___DAT7: #REF!
Name ___DAT7: #REF!
Name ___DAT8: #REF!
Name ___DAT8: #REF!
Name ___DAT9: #REF!
Name ___DAT9: #REF!
Name __DAT1: #REF!
Name __DAT1: #REF!
Name __DAT1: #REF!
Name __DAT1: #REF!
Name __DAT1: #REF!
Name __DAT10: #REF!
Name __DAT10: #REF!
Name __DAT10: #REF!
Name __DAT10: #REF!
Name __DAT10: #REF!
Name __DAT11: #REF!
Name __DAT11: #REF!
Name __DAT11: #REF!
Name __DAT11: #REF!
Name __DAT11: #REF!
Name __DAT12: #REF!
Name __DAT12: #REF!
Name __DAT12: #REF!
Name __DAT12: #REF!
Name __DAT12: #REF!
Name __DAT13: #REF!
Name __DAT13: #REF!
Name __DAT13: #REF!
Name __DAT13: #REF!
Name __DAT13: #REF!
Name __DAT2: #REF!
Name __DAT2: #REF!
Name __DAT2: #REF!
Name __DAT2: #REF!
Name __DAT2: #REF!
Name __DAT3: #REF!
Name __DAT3: #REF!
Name __DAT3: #REF!

Sheet Bush Rejection
K1: 44256 | M1: A | N1: B | O1: C | P1: FQC | S1: COST OF POOR QUALITY
K2: Grand Total:- | M2: =SUBTOTAL(9,M5:M7) -> 0 | N2: =SUBTOTAL(9,#REF!) -> #REF! | O2: =SUBTOTAL(9,O5:O18) -> 0 | P2: =SUBTOTAL(9,#REF!) -> #REF! | Q2: =SUBTOTAL(9,#REF!) -> #REF! | S2: =SUBTOTAL(9,S5:S33) -> #N/A
M3: Rejection Qty
A4: Sr. No | B4: .Code | C4: M/c No | D4: M/c Name | E4: Oprn. | F4: Code | G4: Part No. | H4: Customer | I4: Operator | J4: .Code | K4: Non Conformance | L4: Date | M4: 1st | N4: 2nd | O4: 3rd | P4: FQC | Q4: Total Rej. qty | R4: cost per piece | S4: Total cost | T4: SAP CODE | U4: Code | V4: Reason | W4: Due To 4M | X4: Nature of Problem
A5: 1 | C5: =VLOOKUP(B5,'[1]RE Defect Sheet'!$E$2:$H$38,2,0) -> #N/A | D5: =VLOOKUP(B5,'[1]RE Defect Sheet'!$E$2:$H$38,3,0) -> #N/A | E5: =VLOOKUP(B5,'[1]RE Defect Sheet'!$E$2:$H$38,4,0) -> #N/A | G5: =VLOOKUP(F5,'[1]RE Defect Sheet'!$K$3:$N$176,2,0) -> #N/A | H5: =VLOOKUP(F5,'[1]RE Defect Sheet'!$K$3:$N$176,3,0) -> #N/A | K5: =VLOOKUP(J5,'[1]RE Defect Sheet'!$A$2:$C$58,2,0) -> #N/A | Q5: =M5+N5+O5+P5 -> 0 | R5: =VLOOKUP(F5,'[1]RE Defect Sheet'!$K$3:$N$176,4,0) -> #N/A | S5: =(Q5*R5) -> #N/A | T5: =VLOOKUP(J5,'[1]RE Defect Sheet'!$A$2:$C$49,3,0) -> #N/A | V5: =VLOOKUP(U5,'[1]RE Defect Sheet'!$P$3:$S$67,2,0) -> #N/A | W5: =VLOOKUP(U5,'[1]RE Defect Sheet'!$P$3:$S$67,3,0) -> #N/A | X5: =VLOOKUP(U5,'[1]RE Defect Sheet'!$P$3:$S$67,4,0) -> #N/A
A6: 2 | C6: =VLOOKUP(B6,'[1]RE Defect Sheet'!$E$2:$H$38,2,0) -> #N/A | D6: =VLOOKUP(B6,'[1]RE Defect Sheet'!$E$2:$H$38,3,0) -> #N/A | E6: =VLOOKUP(B6,'[1]RE Defect Sheet'!$E$2:$H$38,4,0) -> #N/A | G6: =VLOOKUP(F6,'[1]RE Defect Sheet'!$K$3:$N$176,2,0) -> #N/A | H6: =VLOOKUP(F6,'[1]RE Defect Sheet'!$K$3:$N$176,3,0) -> #N/A | K6: =VLOOKUP(J6,'[1]RE Defect Sheet'!$A$2:$C$58,2,0) -> #N/A | Q6: =M6+N6+O6+P6 -> 0 | R6: =VLOOKUP(F6,'[1]RE Defect Sheet'!$K$3:$N$176,4,0) -> #N/A | S6: =(Q6*R6) -> #N/A | T6: =VLOOKUP(J6,'[1]RE Defect Sheet'!$A$2:$C$49,3,0) -> #N/A | V6: =VLOOKUP(U6,'[1]RE Defect Sheet'!$P$3:$S$67,2,0) -> #N/A | W6: =VLOOKUP(U6,'[1]RE Defect Sheet'!$P$3:$S$67,3,0) -> #N/A | X6: =VLOOKUP(U6,'[1]RE Defect Sheet'!$P$3:$S$67,4,0) -> #N/A
A7: 3 | C7: =VLOOKUP(B7,'[1]RE Defect Sheet'!$E$2:$H$38,2,0) -> #N/A | D7: =VLOOKUP(B7,'[1]RE Defect Sheet'!$E$2:$H$38,3,0) -> #N/A | E7: =VLOOKUP(B7,'[1]RE Defect Sheet'!$E$2:$H$38,4,0) -> #N/A | G7: =VLOOKUP(F7,'[1]RE Defect Sheet'!$K$3:$N$176,2,0) -> #N/A | H7: =VLOOKUP(F7,'[1]RE Defect Sheet'!$K$3:$N$176,3,0) -> #N/A | K7: =VLOOKUP(J7,'[1]RE Defect Sheet'!$A$2:$C$58,2,0) -> #N/A | Q7: =M7+N7+O7+P7 -> 0 | R7: =VLOOKUP(F7,'[1]RE Defect Sheet'!$K$3:$N$176,4,0) -> #N/A | S7: =(Q7*R7) -> #N/A | T7: =VLOOKUP(J7,'[1]RE Defect Sheet'!$A$2:$C$49,3,0) -> #N/A | V7: =VLOOKUP(U7,'[1]RE Defect Sheet'!$P$3:$S$67,2,0) -> #N/A | W7: =VLOOKUP(U7,'[1]RE Defect Sheet'!$P$3:$S$67,3,0) -> #N/A | X7: =VLOOKUP(U7,'[1]RE Defect Sheet'!$P$3:$S$67,4,0) -> #N/A
A8: 4 | C8: =VLOOKUP(B8,'[1]RE Defect Sheet'!$E$2:$H$38,2,0) -> #N/A | D8: =VLOOKUP(B8,'[1]RE Defect Sheet'!$E$2:$H$38,3,0) -> #N/A | E8: =VLOOKUP(B8,'[1]RE Defect Sheet'!$E$2:$H$38,4,0) -> #N/A | G8: =VLOOKUP(F8,'[1]RE Defect Sheet'!$K$3:$N$176,2,0) -> #N/A | H8: =VLOOKUP(F8,'[1]RE Defect Sheet'!$K$3:$N$176,3,0) -> #N/A | K8: =VLOOKUP(J8,'[1]RE Defect Sheet'!$A$2:$C$58,2,0) -> #N/A | Q8: =M8+N8+O8+P8 -> 0 | R8: =VLOOKUP(F8,'[1]RE Defect Sheet'!$K$3:$N$176,4,0) -> #N/A | S8: =(Q8*R8) -> #N/A | T8: =VLOOKUP(J8,'[1]RE Defect Sheet'!$A$2:$C$49,3,0) -> #N/A | V8: =VLOOKUP(U8,'[1]RE Defect Sheet'!$P$3:$S$67,2,0) -> #N/A | W8: =VLOOKUP(U8,'[1]RE Defect Sheet'!$P$3:$S$67,3,0) -> #N/A | X8: =VLOOKUP(U8,'[1]RE Defect Sheet'!$P$3:$S$67,4,0) -> #N/A
A9: 5 | C9: =VLOOKUP(B9,'[1]RE Defect Sheet'!$E$2:$H$38,2,0) -> #N/A | D9: =VLOOKUP(B9,'[1]RE Defect Sheet'!$E$2:$H$38,3,0) -> #N/A | E9: =VLOOKUP(B9,'[1]RE Defect Sheet'!$E$2:$H$38,4,0) -> #N/A | G9: =VLOOKUP(F9,'[1]RE Defect Sheet'!$K$3:$N$176,2,0) -> #N/A | H9: =VLOOKUP(F9,'[1]RE Defect Sheet'!$K$3:$N$176,3,0) -> #N/A | K9: =VLOOKUP(J9,'[1]RE Defect Sheet'!$A$2:$C$58,2,0) -> #N/A | Q9: =M9+N9+O9+P9 -> 0 | R9: =VLOOKUP(F9,'[1]RE Defect Sheet'!$K$3:$N$176,4,0) -> #N/A | S9: =(Q9*R9) -> #N/A | T9: =VLOOKUP(J9,'[1]RE Defect Sheet'!$A$2:$C$49,3,0) -> #N/A | V9: =VLOOKUP(U9,'[1]RE Defect Sheet'!$P$3:$S$67,2,0) -> #N/A | W9: =VLOOKUP(U9,'[1]RE Defect Sheet'!$P$3:$S$67,3,0) -> #N/A | X9: =VLOOKUP(U9,'[1]RE Defect Sheet'!$P$3:$S$67,4,0) -> #N/A
A10: 6 | C10: =VLOOKUP(B10,'[1]RE Defect Sheet'!$E$2:$H$38,2,0) -> #N/A | D10: =VLOOKUP(B10,'[1]RE Defect Sheet'!$E$2:$H$38,3,0) -> #N/A | E10: =VLOOKUP(B10,'[1]RE Defect Sheet'!$E$2:$H$38,4,0) -> #N/A | G10: =VLOOKUP(F10,'[1]RE Defect Sheet'!$K$3:$N$176,2,0) -> #N/A | H10: =VLOOKUP(F10,'[1]RE Defect Sheet'!$K$3:$N$176,3,0) -> #N/A | K10: =VLOOKUP(J10,'[1]RE Defect Sheet'!$A$2:$C$58,2,0) -> #N/A | Q10: =M10+N10+O10+P10 -> 0 | R10: =VLOOKUP(F10,'[1]RE Defect Sheet'!$K$3:$N$176,4,0) -> #N/A | S10: =(Q10*R10) -> #N/A | T10: =VLOOKUP(J10,'[1]RE Defect Sheet'!$A$2:$C$49,3,0) -> #N/A | V10: =VLOOKUP(U10,'[1]RE Defect Sheet'!$P$3:$S$67,2,0) -> #N/A | W10: =VLOOKUP(U10,'[1]RE Defect Sheet'!$P$3:$S$67,3,0) -> #N/A | X10: =VLOOKUP(U10,'[1]RE Defect Sheet'!$P$3:$S$67,4,0) -> #N/A
A11: 7 | C11: =VLOOKUP(B11,'[1]RE Defect Sheet'!$E$2:$H$38,2,0) -> #N/A | D11: =VLOOKUP(B11,'[1]RE Defect Sheet'!$E$2:$H$38,3,0) -> #N/A | E11: =VLOOKUP(B11,'[1]RE Defect Sheet'!$E$2:$H$38,4,0) -> #N/A | G11: =VLOOKUP(F11,'[1]RE Defect Sheet'!$K$3:$N$176,2,0) -> #N/A | H11: =VLOOKUP(F11,'[1]RE Defect Sheet'!$K$3:$N$176,3,0) -> #N/A | K11: =VLOOKUP(J11,'[1]RE Defect Sheet'!$A$2:$C$58,2,0) -> #N/A | Q11: =M11+N11+O11+P11 -> 0 | R11: =VLOOKUP(F11,'[1]RE Defect Sheet'!$K$3:$N$176,4,0) -> #N/A | S11: =(Q11*R11) -> #N/A | T11: =VLOOKUP(J11,'[1]RE Defect Sheet'!$A$2:$C$49,3,0) -> #N/A | V11: =VLOOKUP(U11,'[1]RE Defect Sheet'!$P$3:$S$67,2,0) -> #N/A | W11: =VLOOKUP(U11,'[1]RE Defect Sheet'!$P$3:$S$67,3,0) -> #N/A | X11: =VLOOKUP(U11,'[1]RE Defect Sheet'!$P$3:$S$67,4,0) -> #N/A
A12: 8 | C12: =VLOOKUP(B12,'[1]RE Defect Sheet'!$E$2:$H$38,2,0) -> #N/A | D12: =VLOOKUP(B12,'[1]RE Defect Sheet'!$E$2:$H$38,3,0) -> #N/A | E12: =VLOOKUP(B12,'[1]RE Defect Sheet'!$E$2:$H$38,4,0) -> #N/A | G12: =VLOOKUP(F12,'[1]RE Defect Sheet'!$K$3:$N$176,2,0) -> #N/A | H12: =VLOOKUP(F12,'[1]RE Defect Sheet'!$K$3:$N$176,3,0) -> #N/A | K12: =VLOOKUP(J12,'[1]RE Defect Sheet'!$A$2:$C$58,2,0) -> #N/A | Q12: =M12+N12+O12+P12 -> 0 | R12: =VLOOKUP(F12,'[1]RE Defect Sheet'!$K$3:$N$176,4,0) -> #N/A | S12: =(Q12*R12) -> #N/A | T12: =VLOOKUP(J12,'[1]RE Defect Sheet'!$A$2:$C$49,3,0) -> #N/A | V12: =VLOOKUP(U12,'[1]RE Defect Sheet'!$P$3:$S$67,2,0) -> #N/A | W12: =VLOOKUP(U12,'[1]RE Defect Sheet'!$P$3:$S$67,3,0) -> #N/A | X12: =VLOOKUP(U12,'[1]RE Defect Sheet'!$P$3:$S$67,4,0) -> #N/A
A13: 9 | C13: =VLOOKUP(B13,'[1]RE Defect Sheet'!$E$2:$H$38,2,0) -> #N/A | D13: =VLOOKUP(B13,'[1]RE Defect Sheet'!$E$2:$H$38,3,0) -> #N/A | E13: =VLOOKUP(B13,'[1]RE Defect Sheet'!$E$2:$H$38,4,0) -> #N/A | G13: =VLOOKUP(F13,'[1]RE Defect Sheet'!$K$3:$N$176,2,0) -> #N/A | H13: =VLOOKUP(F13,'[1]RE Defect Sheet'!$K$3:$N$176,3,0) -> #N/A | K13: =VLOOKUP(J13,'[1]RE Defect Sheet'!$A$2:$C$58,2,0) -> #N/A | Q13: =M13+N13+O13+P13 -> 0 | R13: =VLOOKUP(F13,'[1]RE Defect Sheet'!$K$3:$N$176,4,0) -> #N/A | S13: =(Q13*R13) -> #N/A | T13: =VLOOKUP(J13,'[1]RE Defect Sheet'!$A$2:$C$49,3,0) -> #N/A | V13: =VLOOKUP(U13,'[1]RE Defect Sheet'!$P$3:$S$67,2,0) -> #N/A | W13: =VLOOKUP(U13,'[1]RE Defect Sheet'!$P$3:$S$67,3,0) -> #N/A | X13: =VLOOKUP(U13,'[1]RE Defect Sheet'!$P$3:$S$67,4,0) -> #N/A
A14: 10 | C14: =VLOOKUP(B14,'[1]RE Defect Sheet'!$E$2:$H$38,2,0) -> #N/A | D14: =VLOOKUP(B14,'[1]RE Defect Sheet'!$E$2:$H$38,3,0) -> #N/A | E14: =VLOOKUP(B14,'[1]RE Defect Sheet'!$E$2:$H$38,4,0) -> #N/A | G14: =VLOOKUP(F14,'[1]RE Defect Sheet'!$K$3:$N$176,2,0) -> #N/A | H14: =VLOOKUP(F14,'[1]RE Defect Sheet'!$K$3:$N$176,3,0) -> #N/A | K14: =VLOOKUP(J14,'[1]RE Defect Sheet'!$A$2:$C$58,2,0) -> #N/A | Q14: =M14+N14+O14+P14 -> 0 | R14: =VLOOKUP(F14,'[1]RE Defect Sheet'!$K$3:$N$176,4,0) -> #N/A | S14: =(Q14*R14) -> #N/A | T14: =VLOOKUP(J14,'[1]RE Defect Sheet'!$A$2:$C$49,3,0) -> #N/A | V14: =VLOOKUP(U14,'[1]RE Defect Sheet'!$P$3:$S$67,2,0) -> #N/A | W14: =VLOOKUP(U14,'[1]RE Defect Sheet'!$P$3:$S$67,3,0) -> #N/A | X14: =VLOOKUP(U14,'[1]RE Defect Sheet'!$P$3:$S$67,4,0) -> #N/A
A15: 11 | C15: =VLOOKUP(B15,'[1]RE Defect Sheet'!$E$2:$H$38,2,0) -> #N/A | D15: =VLOOKUP(B15,'[1]RE Defect Sheet'!$E$2:$H$38,3,0) -> #N/A | E15: =VLOOKUP(B15,'[1]RE Defect Sheet'!$E$2:$H$38,4,0) -> #N/A | G15: =VLOOKUP(F15,'[1]RE Defect Sheet'!$K$3:$N$176,2,0) -> #N/A | H15: =VLOOKUP(F15,'[1]RE Defect Sheet'!$K$3:$N$176,3,0) -> #N/A | K15: =VLOOKUP(J15,'[1]RE Defect Sheet'!$A$2:$C$58,2,0) -> #N/A | Q15: =M15+N15+O15+P15 -> 0 | R15: =VLOOKUP(F15,'[1]RE Defect Sheet'!$K$3:$N$176,4,0) -> #N/A | S15: =(Q15*R15) -> #N/A | T15: =VLOOKUP(J15,'[1]RE Defect Sheet'!$A$2:$C$49,3,0) -> #N/A | V15: =VLOOKUP(U15,'[1]RE Defect Sheet'!$P$3:$S$67,2,0) -> #N/A | W15: =VLOOKUP(U15,'[1]RE Defect Sheet'!$P$3:$S$67,3,0) -> #N/A | X15: =VLOOKUP(U15,'[1]RE Defect Sheet'!$P$3:$S$67,4,0) -> #N/A
A16: 12 | C16: =VLOOKUP(B16,'[1]RE Defect Sheet'!$E$2:$H$38,2,0) -> #N/A | D16: =VLOOKUP(B16,'[1]RE Defect Sheet'!$E$2:$H$38,3,0) -> #N/A | E16: =VLOOKUP(B16,'[1]RE Defect Sheet'!$E$2:$H$38,4,0) -> #N/A | G16: =VLOOKUP(F16,'[1]RE Defect Sheet'!$K$3:$N$176,2,0) -> #N/A | H16: =VLOOKUP(F16,'[1]RE Defect Sheet'!$K$3:$N$176,3,0) -> #N/A | K16: =VLOOKUP(J16,'[1]RE Defect Sheet'!$A$2:$C$58,2,0) -> #N/A | Q16: =M16+N16+O16+P16 -> 0 | R16: =VLOOKUP(F16,'[1]RE Defect Sheet'!$K$3:$N$176,4,0) -> #N/A | S16: =(Q16*R16) -> #N/A | T16: =VLOOKUP(J16,'[1]RE Defect Sheet'!$A$2:$C$49,3,0) -> #N/A | V16: =VLOOKUP(U16,'[1]RE Defect Sheet'!$P$3:$S$67,2,0) -> #N/A | W16: =VLOOKUP(U16,'[1]RE Defect Sheet'!$P$3:$S$67,3,0) -> #N/A | X16: =VLOOKUP(U16,'[1]RE Defect Sheet'!$P$3:$S$67,4,0) -> #N/A
... A26: 22 | C26: =VLOOKUP(B26,'[1]RE Defect Sheet'!$E$2:$H$38,2,0) -> #N/A | D26: =VLOOKUP(B26,'[1]RE Defect Sheet'!$E$2:$H$38,3,0) -> #N/A | E26: =VLOOKUP(B26,'[1]RE Defect Sheet'!$E$2:$H$38,4,0) -> #N/A | G26: =VLOOKUP(F26,'[1]RE Defect Sheet'!$K$3:$N$176,2,0) -> #N/A | H26: =VLOOKUP(F26,'[1]RE Defect Sheet'!$K$3:$N$176,3,0) -> #N/A | K26: =VLOOKUP(J26,'[1]RE Defect Sheet'!$A$2:$C$58,2,0) -> #N/A | Q26: =M26+N26+O26+P26 -> 0 | R26: =VLOOKUP(F26,'[1]RE Defect Sheet'!$K$3:$N$176,4,0) -> #N/A | S26: =(Q26*R26) -> #N/A | T26: =VLOOKUP(J26,'[1]RE Defect Sheet'!$A$2:$C$49,3,0) -> #N/A | V26: =VLOOKUP(U26,'[1]RE Defect Sheet'!$P$3:$S$67,2,0) -> #N/A | W26: =VLOOKUP(U26,'[1]RE Defect Sheet'!$P$3:$S$67,3,0) -> #N/A | X26: =VLOOKUP(U26,'[1]RE Defect Sheet'!$P$3:$S$67,4,0) -> #N/A

Sheet FQC Rejection Book
K1: 44256 | M1: A | N1: B | O1: C | P1: FQC | S1: COST OF POOR QUALITY
K2: Grand Total:- | M2: =SUBTOTAL(9,M5:M5) -> 0 | N2: =SUBTOTAL(9,#REF!) -> #REF! | O2: =SUBTOTAL(9,O5:O5) -> 0 | P2: =SUBTOTAL(9,#REF!) -> #REF! | Q2: =SUBTOTAL(9,#REF!) -> #REF! | S2: =SUBTOTAL(9,S5:S9) -> #N/A
M3: Rejection Qty
A4: Sr. No | B4: .Code | C4: M/c No | D4: M/c Name | E4: Oprn. | F4: Code | G4: Part No. | H4: Customer | I4: Operator | J4: .Code | K4: Non Conformance | L4: Date | M4: 1st | N4: 2nd | O4: 3rd | P4: FQC | Q4: Total Rej. qty | R4: cost per piece | S4: Total cost | T4: SAP CODE | U4: Code | V4: Reason | W4: Due To 4M | X4: Nature of Problem
A5: 1 | C5: =VLOOKUP(B5,'[1]RE Defect Sheet'!$E$2:$H$38,2,0) -> #N/A | D5: =VLOOKUP(B5,'[1]RE Defect Sheet'!$E$2:$H$38,3,0) -> #N/A | E5: =VLOOKUP(B5,'[1]RE Defect Sheet'!$E$2:$H$38,4,0) -> #N/A | G5: =VLOOKUP(F5,'[1]RE Defect Sheet'!$K$3:$N$176,2,0) -> #N/A | H5: =VLOOKUP(F5,'[1]RE Defect Sheet'!$K$3:$N$176,3,0) -> #N/A | K5: =VLOOKUP(J5,'[1]RE Defect Sheet'!$A$2:$C$58,2,0) -> #N/A | Q5: =M5+N5+O5+P5 -> 0 | R5: =VLOOKUP(F5,'[1]RE Defect Sheet'!$K$3:$N$176,4,0) -> #N/A | S5: =(Q5*R5) -> #N/A | T5: =VLOOKUP(J5,'[1]RE Defect Sheet'!$A$2:$C$49,3,0) -> #N/A | V5: =VLOOKUP(U5,'[1]RE Defect Sheet'!$P$3:$S$67,2,0) -> #N/A | W5: =VLOOKUP(U5,'[1]RE Defect Sheet'!$P$3:$S$67,3,0) -> #N/A | X5: =VLOOKUP(U5,'[1]RE Defect Sheet'!$P$3:$S$67,4,0) -> #N/A

Sheet Truning Daily Rej-Sep-26
M1: 46266 | N1: A | O1: B | P1: C | Q1: FQC | R1: Total Rej. qty | T1: COST OF POOR QUALITY
M2: Grand Total:- | N2: =SUBTOTAL(9,Table2[1st]) -> 1512 | O2: =SUBTOTAL(9,Table2[2nd]) -> 1025 | P2: =SUBTOTAL(9,Table2[3rd]) -> 644 | Q2: =SUBTOTAL(9,Table2[FQC]) -> 64 | R2: =N2+O2+P2+Q2 -> 3245 | T2: =SUBTOTAL(9,Table2[[Total cost ]]) -> 316861.73
N3: Rejection Qty
A4: Sr No. | B4: Code | C4: M/c No | D4: M/c Name | E4: Oprn. | F4: Code2 | G4: Part No. | H4: Customer | I4: operator | J4: Code3 | K4: Non Conformance | L4: Date | M4: Month | N4: 1st | O4: 2nd | P4: 3rd | Q4: FQC | R4: Total Rej. qty | S4: cost per piece | T4: Total cost | U4: SAP CODE | V4: Code4 | W4: Reason | X4: Rejection Identified at | Y4: Rejection Reason
A5: 1 | B5: 2 | C5: =IFERROR(VLOOKUP(Table2[[#This Row],[Code]],'[2]New Machine sheet'!$A$1:$D$101,2,0),0) -> 282-02 | D5: =IFERROR(VLOOKUP(Table2[[#This Row],[M/c No]],'[2]New Machine sheet'!$B$1:$D$101,2,0),0) -> Mazak | E5: =IFERROR(VLOOKUP(Table2[[#This Row],[M/c Name]],'[2]New Machine sheet'!$C$1:$D$101,2,0),0) -> Turning | F5: 75 | G5: =IFERROR(VLOOKUP(Table2[[#This Row],[Code2]],'[2]New Machine sheet'!$F$2:$I$64,2,),0) -> 2475 | H5: =IFERROR(VLOOKUP(Table2[[#This Row],[Code2]],'[2]New Machine sheet'!$F$2:$I$64,3,0),0) -> RE P1 | I5: Varsha | J5: 5 | K5: =IFERROR(VLOOKUP(Table2[[#This Row],[Code3]],'[2]New defect code '!$A$2:$D$129,2,0),0) -> Bore Over size | L5: 01.09.26 | M5: 46266 | N5: 1 | R5: =SUBTOTAL(9,Table2[[#This Row],[1st]:[FQC]]) -> 1 | S5: =IFERROR(VLOOKUP(Table2[[#This Row],[Part No.]],'[2]New Machine sheet'!$G$2:$I$90,3,0),0) -> 138.77 | T5: =Table2[[#This Row],[cost per piece]]*Table2[[#This Row],[Total Rej. qty]] -> 138.77 | U5: =IFERROR(VLOOKUP(Table2[[#This Row],[Non Conformance]],'[2]New defect code '!$B$2:$C$129,2,0),0) -> 3243 | V5: 18 | W5: =IFERROR(VLOOKUP(Table2[[#This Row],[Code4]],'[2]New Reason code'!$A$2:$D$77,2,0),0) -> During insert change | X5: =IFERROR(VLOOKUP(Table2[[#This Row],[Reason]],'[2]New Reason code'!$B$2:$D$77,2,0),0) -> Due to Settup | Y5: =IFERROR(VLOOKUP(Table2[[#This Row],[Rejection Identified at]],'[2]New Reason code'!$C$2:$D$77,2,0),0) -> skill
A6: 2 | B6: 41 | C6: =IFERROR(VLOOKUP(Table2[[#This Row],[Code]],'[2]New Machine sheet'!$A$1:$D$101,2,0),0) -> 252-03 | D6: =IFERROR(VLOOKUP(Table2[[#This Row],[M/c No]],'[2]New Machine sheet'!$B$1:$D$101,2,0),0) -> VMC | E6: =IFERROR(VLOOKUP(Table2[[#This Row],[M/c Name]],'[2]New Machine sheet'!$C$1:$D$101,2,0),0) -> VMC | F6: 77 | G6: =IFERROR(VLOOKUP(Table2[[#This Row],[Code2]],'[2]New Machine sheet'!$F$2:$I$64,2,),0) -> 2477 | H6: =IFERROR(VLOOKUP(Table2[[#This Row],[Code2]],'[2]New Machine sheet'!$F$2:$I$64,3,0),0) -> RE P1 | I6: Varsha | J6: 72 | K6: =IFERROR(VLOOKUP(Table2[[#This Row],[Code3]],'[2]New defect code '!$A$2:$D$129,2,0),0) -> PG No Go pass | L6: 01.09.26 | M6: 46266 | N6: 1 | R6: =SUBTOTAL(9,Table2[[#This Row],[1st]:[FQC]]) -> 1 | S6: =IFERROR(VLOOKUP(Table2[[#This Row],[Part No.]],'[2]New Machine sheet'!$G$2:$I$90,3,0),0) -> 79.065 | T6: =Table2[[#This Row],[cost per piece]]*Table2[[#This Row],[Total Rej. qty]] -> 79.065 | U6: =IFERROR(VLOOKUP(Table2[[#This Row],[Non Conformance]],'[2]New defect code '!$B$2:$C$129,2,0),0) -> 0 | V6: 21 | W6: =IFERROR(VLOOKUP(Table2[[#This Row],[Code4]],'[2]New Reason code'!$A$2:$D$77,2,0),0) -> During setup time | X6: =IFERROR(VLOOKUP(Table2[[#This Row],[Reason]],'[2]New Reason code'!$B$2:$D$77,2,0),0) -> Due to Settup | Y6: =IFERROR(VLOOKUP(Table2[[#This Row],[Rejection Identified at]],'[2]New Reason code'!$C$2:$D$77,2,0),0) -> skill
A7: 3 | C7: ACE-22 | D7: Micromatic | E7: =IFERROR(VLOOKUP(Table2[[#This Row],[M/c Name]],'[2]New Machine sheet'!$C$1:$D$101,2,0),0) -> Turning | F7: 127 | G7: =IFERROR(VLOOKUP(Table2[[#This Row],[Code2]],'[2]New Machine sheet'!$F$2:$I$64,2,),0) -> 24127 | H7: =IFERROR(VLOOKUP(Table2[[#This Row],[Code2]],'[2]New Machine sheet'!$F$2:$I$64,3,0),0) -> RE J1 | I7: Khushboo | J7: 40 | K7: =IFERROR(VLOOKUP(Table2[[#This Row],[Code3]],'[2]New defect code '!$A$2:$D$129,2,0),0) -> FACE Damage | L7: 01.09.26 | M7: 46266 | N7: 1 | R7: =SUBTOTAL(9,Table2[[#This Row],[1st]:[FQC]]) -> 1 | S7: =IFERROR(VLOOKUP(Table2[[#This Row],[Part No.]],'[2]New Machine sheet'!$G$2:$I$90,3,0),0) -> 262.812 | T7: =Table2[[#This Row],[cost per piece]]*Table2[[#This Row],[Total Rej. qty]] -> 262.812 | U7: =IFERROR(VLOOKUP(Table2[[#This Row],[Non Conformance]],'[2]New defect code '!$B$2:$C$129,2,0),0) -> 3229 | V7: 30 | W7: =IFERROR(VLOOKUP(Table2[[#This Row],[Code4]],'[2]New Reason code'!$A$2:$D$77,2,0),0) -> M/C Accident | X7: =IFERROR(VLOOKUP(Table2[[#This Row],[Reason]],'[2]New Reason code'!$B$2:$D$77,2,0),0) -> Due to machine | Y7: =IFERROR(VLOOKUP(Table2[[#This Row],[Rejection Identified at]],'[2]New Reason code'!$C$2:$D$77,2,0),0) -> process
A8: 4 | B8: 15 | C8: =IFERROR(VLOOKUP(Table2[[#This Row],[Code]],'[2]New Machine sheet'!$A$1:$D$101,2,0),0) -> 282-15 | D8: =IFERROR(VLOOKUP(Table2[[#This Row],[M/c No]],'[2]New Machine sheet'!$B$1:$D$101,2,0),0) -> Mazak | E8: =IFERROR(VLOOKUP(Table2[[#This Row],[M/c Name]],'[2]New Machine sheet'!$C$1:$D$101,2,0),0) -> Turning | F8: 127 | G8: =IFERROR(VLOOKUP(Table2[[#This Row],[Code2]],'[2]New Machine sheet'!$F$2:$I$64,2,),0) -> 24127 | H8: =IFERROR(VLOOKUP(Table2[[#This Row],[Code2]],'[2]New Machine sheet'!$F$2:$I$64,3,0),0) -> RE J1 | I8: Ravina | J8: 93 | K8: =IFERROR(VLOOKUP(Table2[[#This Row],[Code3]],'[2]New defect code '!$A$2:$D$129,2,0),0) -> Thickness Under size | L8: 01.09.26 | M8: 46266 | N8: 2 | R8: =SUBTOTAL(9,Table2[[#This Row],[1st]:[FQC]]) -> 2 | S8: =IFERROR(VLOOKUP(Table2[[#This Row],[Part No.]],'[2]New Machine sheet'!$G$2:$I$90,3,0),0) -> 262.812 | T8: =Table2[[#This Row],[cost per piece]]*Table2[[#This Row],[Total Rej. qty]] -> 525.624 | U8: =IFERROR(VLOOKUP(Table2[[#This Row],[Non Conformance]],'[2]New defect code '!$B$2:$C$129,2,0),0) -> 3258 | V8: 18 | W8: =IFERROR(VLOOKUP(Table2[[#This Row],[Code4]],'[2]New Reason code'!$A$2:$D$77,2,0),0) -> During insert change | X8: =IFERROR(VLOOKUP(Table2[[#This Row],[Reason]],'[2]New Reason code'!$B$2:$D$77,2,0),0) -> Due to Settup | Y8: =IFERROR(VLOOKUP(Table2[[#This Row],[Rejection Identified at]],'[2]New Reason code'!$C$2:$D$77,2,0),0) -> skill
A9: 5 | B9: 15 | C9: =IFERROR(VLOOKUP(Table2[[#This Row],[Code]],'[2]New Machine sheet'!$A$1:$D$101,2,0),0) -> 282-15 | D9: =IFERROR(VLOOKUP(Table2[[#This Row],[M/c No]],'[2]New Machine sheet'!$B$1:$D$101,2,0),0) -> Mazak | E9: =IFERROR(VLOOKUP(Table2[[#This Row],[M/c Name]],'[2]New Machine sheet'!$C$1:$D$101,2,0),0) -> Turning | F9: 187 | G9: =IFERROR(VLOOKUP(Table2[[#This Row],[Code2]],'[2]New Machine sheet'!$F$2:$I$64,2,),0) -> 24187 | H9: =IFERROR(VLOOKUP(Table2[[#This Row],[Code2]],'[2]New Machine sheet'!$F$2:$I$64,3,0),0) -> RE Bush | I9: Ravina | J9: 21 | K9: =IFERROR(VLOOKUP(Table2[[#This Row],[Code3]],'[2]New defect code '!$A$2:$D$129,2,0),0) -> Bush Reject of defective part | L9: 01.09.26 | M9: 46266 | N9: 2 | R9: =SUBTOTAL(9,Table2[[#This Row],[1st]:[FQC]]) -> 2 | S9: =IFERROR(VLOOKUP(Table2[[#This Row],[Part No.]],'[2]New Machine sheet'!$G$2:$I$90,3,0),0) -> 21.77 | T9: =Table2[[#This Row],[cost per piece]]*Table2[[#This Row],[Total Rej. qty]] -> 43.54 | U9: =IFERROR(VLOOKUP(Table2[[#This Row],[Non Conformance]],'[2]New defect code '!$B$2:$C$129,2,0),0) -> 0 | V9: 6 | W9: =IFERROR(VLOOKUP(Table2[[#This Row],[Code4]],'[2]New Reason code'!$A$2:$D$77,2,0),0) -> bush will not use again | X9: =IFERROR(VLOOKUP(Table2[[#This Row],[Reason]],'[2]New Reason code'!$B$2:$D$77,2,0),0) -> Prod Declared | Y9: =IFERROR(VLOOKUP(Table2[[#This Row],[Rejection Identified at]],'[2]New Reason code'!$C$2:$D$77,2,0),0) -> Process Issue
A10: 6 | B10: 40 | C10: =IFERROR(VLOOKUP(Table2[[#This Row],[Code]],'[2]New Machine sheet'!$A$1:$D$101,2,0),0) -> ACE-20 | D10: =IFERROR(VLOOKUP(Table2[[#This Row],[M/c No]],'[2]New Machine sheet'!$B$1:$D$101,2,0),0) -> Micromatic | E10: =IFERROR(VLOOKUP(Table2[[#This Row],[M/c Name]],'[2]New Machine sheet'!$C$1:$D$101,2,0),0) -> Turning | F10: 122 | G10: =IFERROR(VLOOKUP(Table2[[#This Row],[Code2]],'[2]New Machine sheet'!$F$2:$I$64,2,),0) -> 24122 | H10: =IFERROR(VLOOKUP(Table2[[#This Row],[Code2]],'[2]New Machine sheet'!$F$2:$I$64,3,0),0) -> RE J1 | I10: Ravina | J10: 93 | K10: =IFERROR(VLOOKUP(Table2[[#This Row],[Code3]],'[2]New defect code '!$A$2:$D$129,2,0),0) -> Thickness Under size | L10: 01.09.26 | M10: 46266 | N10: 1 | R10: =SUBTOTAL(9,Table2[[#This Row],[1st]:[FQC]]) -> 1 | S10: =IFERROR(VLOOKUP(Table2[[#This Row],[Part No.]],'[2]New Machine sheet'!$G$2:$I$90,3,0),0) -> 335.39978 | T10: =Table2[[#This Row],[cost per piece]]*Table2[[#This Row],[Total Rej. qty]] -> 335.39978 | U10: =IFERROR(VLOOKUP(Table2[[#This Row],[Non Conformance]],'[2]New defect code '!$B$2:$C$129,2,0),0) -> 3258 | V10: 18 | W10: =IFERROR(VLOOKUP(Table2[[#This Row],[Code4]],'[2]New Reason code'!$A$2:$D$77,2,0),0) -> During insert change | X10: =IFERROR(VLOOKUP(Table2[[#This Row],[Reason]],'[2]New Reason code'!$B$2:$D$77,2,0),0) -> Due to Settup | Y10: =IFERROR(VLOOKUP(Table2[[#This Row],[Rejection Identified at]],'[2]New Reason code'!$C$2:$D$77,2,0),0) -> skill
A11: 7 | B11: 43 | C11: =IFERROR(VLOOKUP(Table2[[#This Row],[Code]],'[2]New Machine sheet'!$A$1:$D$101,2,0),0) -> 252-05 | D11: =IFERROR(VLOOKUP(Table2[[#This Row],[M/c No]],'[2]New Machine sheet'!$B$1:$D$101,2,0),0) -> VMC | E11: =IFERROR(VLOOKUP(Table2[[#This Row],[M/c Name]],'[2]New Machine sheet'!$C$1:$D$101,2,0),0) -> VMC | F11: 155 | G11: =IFERROR(VLOOKUP(Table2[[#This Row],[Code2]],'[2]New Machine sheet'!$F$2:$I$64,2,),0) -> 24155 | H11: =IFERROR(VLOOKUP(Table2[[#This Row],[Code2]],'[2]New Machine sheet'!$F$2:$I$64,3,0),0) -> RE J1 | I11: Shubham | J11: 34 | K11: =IFERROR(VLOOKUP(Table2[[#This Row],[Code3]],'[2]New defect code '!$A$2:$D$129,2,0),0) -> Dowel hole not ok | L11: 01.09.26 | M11: 46266 | N11: 2 | R11: =SUBTOTAL(9,Table2[[#This Row],[1st]:[FQC]]) -> 2 | S11: =IFERROR(VLOOKUP(Table2[[#This Row],[Part No.]],'[2]New Machine sheet'!$G$2:$I$90,3,0),0) -> 107.67 | T11: =Table2[[#This Row],[cost per piece]]*Table2[[#This Row],[Total Rej. qty]] -> 215.34 | U11: =IFERROR(VLOOKUP(Table2[[#This Row],[Non Conformance]],'[2]New defect code '!$B$2:$C$129,2,0),0) -> 3221 | V11: 66 | W11: =IFERROR(VLOOKUP(Table2[[#This Row],[Code4]],'[2]New Reason code'!$A$2:$D$77,2,0),0) -> Wrong Loading | X11: =IFERROR(VLOOKUP(Table2[[#This Row],[Reason]],'[2]New Reason code'!$B$2:$D$77,2,0),0) -> Due to operator | Y11: =IFERROR(VLOOKUP(Table2[[#This Row],[Rejection Identified at]],'[2]New Reason code'!$C$2:$D$77,2,0),0) -> infrastructure
A12: 8 | B12: 4 | C12: =IFERROR(VLOOKUP(Table2[[#This Row],[Code]],'[2]New Machine sheet'!$A$1:$D$101,2,0),0) -> 282-04 | D12: =IFERROR(VLOOKUP(Table2[[#This Row],[M/c No]],'[2]New Machine sheet'!$B$1:$D$101,2,0),0) -> Mazak | E12: =IFERROR(VLOOKUP(Table2[[#This Row],[M/c Name]],'[2]New Machine sheet'!$C$1:$D$101,2,0),0) -> Turning | F12: 155 | G12: =IFERROR(VLOOKUP(Table2[[#This Row],[Code2]],'[2]New Machine sheet'!$F$2:$I$64,2,),0) -> 24155 | H12: =IFERROR(VLOOKUP(Table2[[#This Row],[Code2]],'[2]New Machine sheet'!$F$2:$I$64,3,0),0) -> RE J1 | I12: Aarti | J12: 5 | K12: =IFERROR(VLOOKUP(Table2[[#This Row],[Code3]],'[2]New defect code '!$A$2:$D$129,2,0),0) -> Bore Over size | L12: 01.09.26 | M12: 46266 | N12: 1 | R12: =SUBTOTAL(9,Table2[[#This Row],[1st]:[FQC]]) -> 1 | S12: =IFERROR(VLOOKUP(Table2[[#This Row],[Part No.]],'[2]New Machine sheet'!$G$2:$I$90,3,0),0) -> 107.67 | T12: =Table2[[#This Row],[cost per piece]]*Table2[[#This Row],[Total Rej. qty]] -> 107.67 | U12: =IFERROR(VLOOKUP(Table2[[#This Row],[Non Conformance]],'[2]New defect code '!$B$2:$C$129,2,0),0) -> 3243 | V12: 12 | W12: =IFERROR(VLOOKUP(Table2[[#This Row],[Code4]],'[2]New Reason code'!$A$2:$D$77,2,0),0) -> Double loading | X12: =IFERROR(VLOOKUP(Table2[[#This Row],[Reason]],'[2]New Reason code'!$B$2:$D$77,2,0),0) -> Due to operator | Y12: =IFERROR(VLOOKUP(Table2[[#This Row],[Rejection Identified at]],'[2]New Reason code'!$C$2:$D$77,2,0),0) -> infrastructure
A13: 9 | B13: 20 | C13: =IFERROR(VLOOKUP(Table2[[#This Row],[Code]],'[2]New Machine sheet'!$A$1:$D$101,2,0),0) -> 282-20 | D13: =IFERROR(VLOOKUP(Table2[[#This Row],[M/c No]],'[2]New Machine sheet'!$B$1:$D$101,2,0),0) -> Mazak | E13: =IFERROR(VLOOKUP(Table2[[#This Row],[M/c Name]],'[2]New Machine sheet'!$C$1:$D$101,2,0),0) -> Turning | F13: 115 | G13: =IFERROR(VLOOKUP(Table2[[#This Row],[Code2]],'[2]New Machine sheet'!$F$2:$I$64,2,),0) -> 24115 | H13: =IFERROR(VLOOKUP(Table2[[#This Row],[Code2]],'[2]New Machine sheet'!$F$2:$I$64,3,0),0) -> RE J1 | I13: Vika | J13: 5 | K13: =IFERROR(VLOOKUP(Table2[[#This Row],[Code3]],'[2]New defect code '!$A$2:$D$129,2,0),0) -> Bore Over size | L13: 01.09.26 | M13: 46266 | N13: 7 | R13: =SUBTOTAL(9,Table2[[#This Row],[1st]:[FQC]]) -> 7 | S13: =IFERROR(VLOOKUP(Table2[[#This Row],[Part No.]],'[2]New Machine sheet'!$G$2:$I$90,3,0),0) -> 66.9 | T13: =Table2[[#This Row],[cost per piece]]*Table2[[#This Row],[Total Rej. qty]] -> 468.3 | U13: =IFERROR(VLOOKUP(Table2[[#This Row],[Non Conformance]],'[2]New defect code '!$B$2:$C$129,2,0),0) -> 3243 | V13: 70 | W13: =IFERROR(VLOOKUP(Table2[[#This Row],[Code4]],'[2]New Reason code'!$A$2:$D$77,2,0),0) -> Insert Wear Out | X13: =IFERROR(VLOOKUP(Table2[[#This Row],[Reason]],'[2]New Reason code'!$B$2:$D$77,2,0),0) -> Line audit | Y13: =IFERROR(VLOOKUP(Table2[[#This Row],[Rejection Identified at]],'[2]New Reason code'!$C$2:$D$77,2,0),0) -> Process Issue
A14: 10 | B14: 5 | C14: =IFERROR(VLOOKUP(Table2[[#This Row],[Code]],'[2]New Machine sheet'!$A$1:$D$101,2,0),0) -> 282-05 | D14: =IFERROR(VLOOKUP(Table2[[#This Row],[M/c No]],'[2]New Machine sheet'!$B$1:$D$101,2,0),0) -> Mazak | E14: =IFERROR(VLOOKUP(Table2[[#This Row],[M/c Name]],'[2]New Machine sheet'!$C$1:$D$101,2,0),0) -> Turning | F14: 119 | G14: =IFERROR(VLOOKUP(Table2[[#This Row],[Code2]],'[2]New Machine sheet'!$F$2:$I$64,2,),0) -> 24119 | H14: =IFERROR(VLOOKUP(Table2[[#This Row],[Code2]],'[2]New Machine sheet'!$F$2:$I$64,3,0),0) -> RE J1 | I14: Vasna | J14: 5 | K14: =IFERROR(VLOOKUP(Table2[[#This Row],[Code3]],'[2]New defect code '!$A$2:$D$129,2,0),0) -> Bore Over size | L14: 01.09.26 | M14: 46266 | N14: 2 | R14: =SUBTOTAL(9,Table2[[#This Row],[1st]:[FQC]]) -> 2 | S14: =IFERROR(VLOOKUP(Table2[[#This Row],[Part No.]],'[2]New Machine sheet'!$G$2:$I$90,3,0),0) -> 103.2 | T14: =Table2[[#This Row],[cost per piece]]*Table2[[#This Row],[Total Rej. qty]] -> 206.4 | U14: =IFERROR(VLOOKUP(Table2[[#This Row],[Non Conformance]],'[2]New defect code '!$B$2:$C$129,2,0),0) -> 3243 | V14: 18 | W14: =IFERROR(VLOOKUP(Table2[[#This Row],[Code4]],'[2]New Reason code'!$A$2:$D$77,2,0),0) -> During insert change | X14: =IFERROR(VLOOKUP(Table2[[#This Row],[Reason]],'[2]New Reason code'!$B$2:$D$77,2,0),0) -> Due to Settup | Y14: =IFERROR(VLOOKUP(Table2[[#This Row],[Rejection Identified at]],'[2]New Reason code'!$C$2:$D$77,2,0),0) -> skill
A15: 11 | B15: 8 | C15: =IFERROR(VLOOKUP(Table2[[#This Row],[Code]],'[2]New Machine sheet'!$A$1:$D$101,2,0),0) -> 282-08 | D15: =IFERROR(VLOOKUP(Table2[[#This Row],[M/c No]],'[2]New Machine sheet'!$B$1:$D$101,2,0),0) -> Mazak | E15: =IFERROR(VLOOKUP(Table2[[#This Row],[M/c Name]],'[2]New Machine sheet'!$C$1:$D$101,2,0),0) -> Turning | F15: 117 | G15: =IFERROR(VLOOKUP(Table2[[#This Row],[Code2]],'[2]New Machine sheet'!$F$2:$I$64,2,),0) -> 24117 | H15: =IFERROR(VLOOKUP(Table2[[#This Row],[Code2]],'[2]New Machine sheet'!$F$2:$I$64,3,0),0) -> RE J1 | I15: Sonu | J15: 5 | K15: =IFERROR(VLOOKUP(Table2[[#This Row],[Code3]],'[2]New defect code '!$A$2:$D$129,2,0),0) -> Bore Over size | L15: 01.09.26 | M15: 46266 | N15: 1 | R15: =SUBTOTAL(9,Table2[[#This Row],[1st]:[FQC]]) -> 1 | S15: =IFERROR(VLOOKUP(Table2[[#This Row],[Part No.]],'[2]New Machine sheet'!$G$2:$I$90,3,0),0) -> 111.97 | T15: =Table2[[#This Row],[cost per piece]]*Table2[[#This Row],[Total Rej. qty]] -> 111.97 | U15: =IFERROR(VLOOKUP(Table2[[#This Row],[Non Conformance]],'[2]New defect code '!$B$2:$C$129,2,0),0) -> 3243 | V15: 18 | W15: =IFERROR(VLOOKUP(Table2[[#This Row],[Code4]],'[2]New Reason code'!$A$2:$D$77,2,0),0) -> During insert change | X15: =IFERROR(VLOOKUP(Table2[[#This Row],[Reason]],'[2]New Reason code'!$B$2:$D$77,2,0),0) -> Due to Settup | Y15: =IFERROR(VLOOKUP(Table2[[#This Row],[Rejection Identified at]],'[2]New Reason code'!$C$2:$D$77,2,0),0) -> skill
A16: 12 | B16: 10 | C16: =IFERROR(VLOOKUP(Table2[[#This Row],[Code]],'[2]New Machine sheet'!$A$1:$D$101,2,0),0) -> 282-10 | D16: =IFERROR(VLOOKUP(Table2[[#This Row],[M/c No]],'[2]New Machine sheet'!$B$1:$D$101,2,0),0) -> Mazak | E16: =IFERROR(VLOOKUP(Table2[[#This Row],[M/c Name]],'[2]New Machine sheet'!$C$1:$D$101,2,0),0) -> Turning | F16: 155 | G16: =IFERROR(VLOOKUP(Table2[[#This Row],[Code2]],'[2]New Machine sheet'!$F$2:$I$64,2,),0) -> 24155 | H16: =IFERROR(VLOOKUP(Table2[[#This Row],[Code2]],'[2]New Machine sheet'!$F$2:$I$64,3,0),0) -> RE J1 | I16: Ritu | J16: 5 | K16: =IFERROR(VLOOKUP(Table2[[#This Row],[Code3]],'[2]New defect code '!$A$2:$D$129,2,0),0) -> Bore Over size | L16: 01.09.26 | M16: 46266 | N16: 1 | R16: =SUBTOTAL(9,Table2[[#This Row],[1st]:[FQC]]) -> 1 | S16: =IFERROR(VLOOKUP(Table2[[#This Row],[Part No.]],'[2]New Machine sheet'!$G$2:$I$90,3,0),0) -> 107.67 | T16: =Table2[[#This Row],[cost per piece]]*Table2[[#This Row],[Total Rej. qty]] -> 107.67 | U16: =IFERROR(VLOOKUP(Table2[[#This Row],[Non Conformance]],'[2]New defect code '!$B$2:$C$129,2,0),0) -> 3243 | V16: 18 | W16: =IFERROR(VLOOKUP(Table2[[#This Row],[Code4]],'[2]New Reason code'!$A$2:$D$77,2,0),0) -> During insert change | X16: =IFERROR(VLOOKUP(Table2[[#This Row],[Reason]],'[2]New Reason code'!$B$2:$D$77,2,0),0) -> Due to Settup | Y16: =IFERROR(VLOOKUP(Table2[[#This Row],[Rejection Identified at]],'[2]New Reason code'!$C$2:$D$77,2,0),0) -> skill
A17: 13 | C17: ACE-23 | D17: Micromatic | E17: =IFERROR(VLOOKUP(Table2[[#This Row],[M/c Name]],'[2]New Machine sheet'!$C$1:$D$101,2,0),0) -> Turning | F17: 119 | G17: =IFERROR(VLOOKUP(Table2[[#This Row],[Code2]],'[2]New Machine sheet'!$F$2:$I$64,2,),0) -> 24119 | H17: =IFERROR(VLOOKUP(Table2[[#This Row],[Code2]],'[2]New Machine sheet'!$F$2:$I$64,3,0),0) -> RE J1 | I17: Aarti | J17: 5 | K17: =IFERROR(VLOOKUP(Table2[[#This Row],[Code3]],'[2]New defect code '!$A$2:$D$129,2,0),0) -> Bore Over size | L17: 01.09.26 | M17: 46266 | N17: 1 | R17: =SUBTOTAL(9,Table2[[#This Row],[1st]:[FQC]]) -> 1 | S17: =IFERROR(VLOOKUP(Table2[[#This Row],[Part No.]],'[2]New Machine sheet'!$G$2:$I$90,3,0),0) -> 103.2 | T17: =Table2[[#This Row],[cost per piece]]*Table2[[#This Row],[Total Rej. qty]] -> 103.2 | U17: =IFERROR(VLOOKUP(Table2[[#This Row],[Non Conformance]],'[2]New defect code '!$B$2:$C$129,2,0),0) -> 3243 | V17: 45 | W17: =IFERROR(VLOOKUP(Table2[[#This Row],[Code4]],'[2]New Reason code'!$A$2:$D$77,2,0),0) -> Running m/c | X17: =IFERROR(VLOOKUP(Table2[[#This Row],[Reason]],'[2]New Reason code'!$B$2:$D$77,2,0),0) -> Due to machine | Y17: =IFERROR(VLOOKUP(Table2[[#This Row],[Rejection Identified at]],'[2]New Reason code'!$C$2:$D$77,2,0),0) -> process
A18: 14 | B18: 21 | C18: =IFERROR(VLOOKUP(Table2[[#This Row],[Code]],'[2]New Machine sheet'!$A$1:$D$101,2,0),0) -> ACE-01 | D18: =IFERROR(VLOOKUP(Table2[[#This Row],[M/c No]],'[2]New Machine sheet'!$B$1:$D$101,2,0),0) -> Micromatic | E18: =IFERROR(VLOOKUP(Table2[[#This Row],[M/c Name]],'[2]New Machine sheet'!$C$1:$D$101,2,0),0) -> Turning | F18: 121 | G18: =IFERROR(VLOOKUP(Table2[[#This Row],[Code2]],'[2]New Machine sheet'!$F$2:$I$64,2,),0) -> 24121 | H18: =IFERROR(VLOOKUP(Table2[[#This Row],[Code2]],'[2]New Machine sheet'!$F$2:$I$64,3,0),0) -> RE J1 | I18: Deepak | J18: 5 | K18: =IFERROR(VLOOKUP(Table2[[#This Row],[Code3]],'[2]New defect code '!$A$2:$D$129,2,0),0) -> Bore Over size | L18: 01.09.26 | M18: 46266 | N18: 1 | R18: =SUBTOTAL(9,Table2[[#This Row],[1st]:[FQC]]) -> 1 | S18: =IFERROR(VLOOKUP(Table2[[#This Row],[Part No.]],'[2]New Machine sheet'!$G$2:$I$90,3,0),0) -> 135.67 | T18: =Table2[[#This Row],[cost per piece]]*Table2[[#This Row],[Total Rej. qty]] -> 135.67 | U18: =IFERROR(VLOOKUP(Table2[[#This Row],[Non Conformance]],'[2]New defect code '!$B$2:$C$129,2,0),0) -> 3243 | V18: 12 | W18: =IFERROR(VLOOKUP(Table2[[#This Row],[Code4]],'[2]New Reason code'!$A$2:$D$77,2,0),0) -> Double loading | X18: =IFERROR(VLOOKUP(Table2[[#This Row],[Reason]],'[2]New Reason code'!$B$2:$D$77,2,0),0) -> Due to operator | Y18: =IFERROR(VLOOKUP(Table2[[#This Row],[Rejection Identified at]],'[2]New Reason code'!$C$2:$D$77,2,0),0) -> infrastructure
A19: 15 | B19: 14 | C19: =IFERROR(VLOOKUP(Table2[[#This Row],[Code]],'[2]New Machine sheet'!$A$1:$D$101,2,0),0) -> 282-14 | D19: =IFERROR(VLOOKUP(Table2[[#This Row],[M/c No]],'[2]New Machine sheet'!$B$1:$D$101,2,0),0) -> Mazak | E19: =IFERROR(VLOOKUP(Table2[[#This Row],[M/c Name]],'[2]New Machine sheet'!$C$1:$D$101,2,0),0) -> Turning | F19: 155 | G19: =IFERROR(VLOOKUP(Table2[[#This Row],[Code2]],'[2]New Machine sheet'!$F$2:$I$64,2,),0) -> 24155 | H19: =IFERROR(VLOOKUP(Table2[[#This Row],[Code2]],'[2]New Machine sheet'!$F$2:$I$64,3,0),0) -> RE J1 | I19: Aarti | J19: 93 | K19: =IFERROR(VLOOKUP(Table2[[#This Row],[Code3]],'[2]New defect code '!$A$2:$D$129,2,0),0) -> Thickness Under size | L19: 01.09.26 | M19: 46266 | N19: 1 | R19: =SUBTOTAL(9,Table2[[#This Row],[1st]:[FQC]]) -> 1 | S19: =IFERROR(VLOOKUP(Table2[[#This Row],[Part No.]],'[2]New Machine sheet'!$G$2:$I$90,3,0),0) -> 107.67 | T19: =Table2[[#This Row],[cost per piece]]*Table2[[#This Row],[Total Rej. qty]] -> 107.67 | U19: =IFERROR(VLOOKUP(Table2[[#This Row],[Non Conformance]],'[2]New defect code '!$B$2:$C$129,2,0),0) -> 3258 | V19: 18 | W19: =IFERROR(VLOOKUP(Table2[[#This Row],[Code4]],'[2]New Reason code'!$A$2:$D$77,2,0),0) -> During insert change | X19: =IFERROR(VLOOKUP(Table2[[#This Row],[Reason]],'[2]New Reason code'!$B$2:$D$77,2,0),0) -> Due to Settup | Y19: =IFERROR(VLOOKUP(Table2[[#This Row],[Rejection Identified at]],'[2]New Reason code'!$C$2:$D$77,2,0),0) -> skill
A20: 16 | B20: 20 | C20: =IFERROR(VLOOKUP(Table2[[#This Row],[Code]],'[2]New Machine sheet'!$A$1:$D$101,2,0),0) -> 282-20 | D20: =IFERROR(VLOOKUP(Table2[[#This Row],[M/c No]],'[2]New Machine sheet'!$B$1:$D$101,2,0),0) -> Mazak | E20: =IFERROR(VLOOKUP(Table2[[#This Row],[M/c Name]],'[2]New Machine sheet'!$C$1:$D$101,2,0),0) -> Turning | F20: 115 | G20: =IFERROR(VLOOKUP(Table2[[#This Row],[Code2]],'[2]New Machine sheet'!$F$2:$I$64,2,),0) -> 24115 | H20: =IFERROR(VLOOKUP(Table2[[#This Row],[Code2]],'[2]New Machine sheet'!$F$2:$I$64,3,0),0) -> RE J1 | J20: 5 | K20: =IFERROR(VLOOKUP(Table2[[#This Row],[Code3]],'[2]New defect code '!$A$2:$D$129,2,0),0) -> Bore Over size | L20: 01.09.26 | M20: 46266 | N20: 9 | R20: =SUBTOTAL(9,Table2[[#This Row],[1st]:[FQC]]) -> 9 | S20: =IFERROR(VLOOKUP(Table2[[#This Row],[Part No.]],'[2]New Machine sheet'!$G$2:$I$90,3,0),0) -> 66.9 | T20: =Table2[[#This Row],[cost per piece]]*Table2[[#This Row],[Total Rej. qty]] -> 602.1 | U20: =IFERROR(VLOOKUP(Table2[[#This Row],[Non Conformance]],'[2]New defect code '!$B$2:$C$129,2,0),0) -> 3243 | V20: 19 | W20: =IFERROR(VLOOKUP(Table2[[#This Row],[Code4]],'[2]New Reason code'!$A$2:$D$77,2,0),0) -> During Rework time | X20: =IFERROR(VLOOKUP(Table2[[#This Row],[Reason]],'[2]New Reason code'!$B$2:$D$77,2,0),0) -> Due to operator | Y20: =IFERROR(VLOOKUP(Table2[[#This Row],[Rejection Identified at]],'[2]New Reason code'!$C$2:$D$77,2,0),0) -> infrastructure
A21: 17 | B21: 20 | C21: =IFERROR(VLOOKUP(Table2[[#This Row],[Code]],'[2]New Machine sheet'!$A$1:$D$101,2,0),0) -> 282-20 | D21: =IFERROR(VLOOKUP(Table2[[#This Row],[M/c No]],'[2]New Machine sheet'!$B$1:$D$101,2,0),0) -> Mazak | E21: =IFERROR(VLOOKUP(Table2[[#This Row],[M/c Name]],'[2]New Machine sheet'!$C$1:$D$101,2,0),0) -> Turning | F21: 115 | G21: =IFERROR(VLOOKUP(Table2[[#This Row],[Code2]],'[2]New Machine sheet'!$F$2:$I$64,2,),0) -> 24115 | H21: =IFERROR(VLOOKUP(Table2[[#This Row],[Code2]],'[2]New Machine sheet'!$F$2:$I$64,3,0),0) -> RE J1 | J21: 93 | K21: =IFERROR(VLOOKUP(Table2[[#This Row],[Code3]],'[2]New defect code '!$A$2:$D$129,2,0),0) -> Thickness Under size | L21: 01.09.26 | M21: 46266 | N21: 6 | R21: =SUBTOTAL(9,Table2[[#This Row],[1st]:[FQC]]) -> 6 | S21: =IFERROR(VLOOKUP(Table2[[#This Row],[Part No.]],'[2]New Machine sheet'!$G$2:$I$90,3,0),0) -> 66.9 | T21: =Table2[[#This Row],[cost per piece]]*Table2[[#This Row],[Total Rej. qty]] -> 401.4 | U21: =IFERROR(VLOOKUP(Table2[[#This Row],[Non Conformance]],'[2]New defect code '!$B$2:$C$129,2,0),0) -> 3258 | V21: 19 | W21: =IFERROR(VLOOKUP(Table2[[#This Row],[Code4]],'[2]New Reason code'!$A$2:$D$77,2,0),0) -> During Rework time | X21: =IFERROR(VLOOKUP(Table2[[#This Row],[Reason]],'[2]New Reason code'!$B$2:$D$77,2,0),0) -> Due to operator | Y21: =IFERROR(VLOOKUP(Table2[[#This Row],[Rejection Identified at]],'[2]New Reason code'!$C$2:$D$77,2,0),0) -> infrastructure
A22: 18 | B22: 13 | C22: =IFERROR(VLOOKUP(Table2[[#This Row],[Code]],'[2]New Machine sheet'!$A$1:$D$101,2,0),0) -> 282-13 | D22: =IFERROR(VLOOKUP(Table2[[#This Row],[M/c No]],'[2]New Machine sheet'!$B$1:$D$101,2,0),0) -> Mazak | E22: =IFERROR(VLOOKUP(Table2[[#This Row],[M/c Name]],'[2]New Machine sheet'!$C$1:$D$101,2,0),0) -> Turning | F22: 113 | G22: =IFERROR(VLOOKUP(Table2[[#This Row],[Code2]],'[2]New Machine sheet'!$F$2:$I$64,2,),0) -> 24113 | H22: =IFERROR(VLOOKUP(Table2[[#This Row],[Code2]],'[2]New Machine sheet'!$F$2:$I$64,3,0),0) -> RE J1 | I22: Ravendra | J22: 5 | K22: =IFERROR(VLOOKUP(Table2[[#This Row],[Code3]],'[2]New defect code '!$A$2:$D$129,2,0),0) -> Bore Over size | L22: 01.09.26 | M22: 46266 | N22: 9 | R22: =SUBTOTAL(9,Table2[[#This Row],[1st]:[FQC]]) -> 9 | S22: =IFERROR(VLOOKUP(Table2[[#This Row],[Part No.]],'[2]New Machine sheet'!$G$2:$I$90,3,0),0) -> 90 | T22: =Table2[[#This Row],[cost per piece]]*Table2[[#This Row],[Total Rej. qty]] -> 810 | U22: =IFERROR(VLOOKUP(Table2[[#This Row],[Non Conformance]],'[2]New defect code '!$B$2:$C$129,2,0),0) -> 3243 | V22: 19 | W22: =IFERROR(VLOOKUP(Table2[[#This Row],[Code4]],'[2]New Reason code'!$A$2:$D$77,2,0),0) -> During Rework time | X22: =IFERROR(VLOOKUP(Table2[[#This Row],[Reason]],'[2]New Reason code'!$B$2:$D$77,2,0),0) -> Due to operator | Y22: =IFERROR(VLOOKUP(Table2[[#This Row],[Rejection Identified at]],'[2]New Reason code'!$C$2:$D$77,2,0),0) -> infrastructure
A23: 19 | B23: 13 | C23: =IFERROR(VLOOKUP(Table2[[#This Row],[Code]],'[2]New Machine sheet'!$A$1:$D$101,2,0),0) -> 282-13 | D23: =IFERROR(VLOOKUP(Table2[[#This Row],[M/c No]],'[2]New Machine sheet'!$B$1:$D$101,2,0),0) -> Mazak | E23: =IFERROR(VLOOKUP(Table2[[#This Row],[M/c Name]],'[2]New Machine sheet'!$C$1:$D$101,2,0),0) -> Turning | F23: 113 | G23: =IFERROR(VLOOKUP(Table2[[#This Row],[Code2]],'[2]New Machine sheet'!$F$2:$I$64,2,),0) -> 24113 | H23: =IFERROR(VLOOKUP(Table2[[#This Row],[Code2]],'[2]New Machine sheet'!$F$2:$I$64,3,0),0) -> RE J1 | I23: Ravendra | J23: 93 | K23: =IFERROR(VLOOKUP(Table2[[#This Row],[Code3]],'[2]New defect code '!$A$2:$D$129,2,0),0) -> Thickness Under size | L23: 01.09.26 | M23: 46266 | N23: 8 | R23: =SUBTOTAL(9,Table2[[#This Row],[1st]:[FQC]]) -> 8 | S23: =IFERROR(VLOOKUP(Table2[[#This Row],[Part No.]],'[2]New Machine sheet'!$G$2:$I$90,3,0),0) -> 90 | T23: =Table2[[#This Row],[cost per piece]]*Table2[[#This Row],[Total Rej. qty]] -> 720 | U23: =IFERROR(VLOOKUP(Table2[[#This Row],[Non Conformance]],'[2]New defect code '!$B$2:$C$129,2,0),0) -> 3258 | V23: 19 | W23: =IFERROR(VLOOKUP(Table2[[#This Row],[Code4]],'[2]New Reason code'!$A$2:$D$77,2,0),0) -> During Rework time | X23: =IFERROR(VLOOKUP(Table2[[#This Row],[Reason]],'[2]New Reason code'!$B$2:$D$77,2,0),0) -> Due to operator | Y23: =IFERROR(VLOOKUP(Table2[[#This Row],[Rejection Identified at]],'[2]New Reason code'!$C$2:$D$77,2,0),0) -> infrastructure
A24: 20 | B24: 21 | C24: =IFERROR(VLOOKUP(Table2[[#This Row],[Code]],'[2]New Machine sheet'!$A$1:$D$101,2,0),0) -> ACE-01 | D24: =IFERROR(VLOOKUP(Table2[[#This Row],[M/c No]],'[2]New Machine sheet'!$B$1:$D$101,2,0),0) -> Micromatic | E24: =IFERROR(VLOOKUP(Table2[[#This Row],[M/c Name]],'[2]New Machine sheet'!$C$1:$D$101,2,0),0) -> Turning | F24: 121 | G24: =IFERROR(VLOOKUP(Table2[[#This Row],[Code2]],'[2]New Machine sheet'!$F$2:$I$64,2,),0) -> 24121 | H24: =IFERROR(VLOOKUP(Table2[[#This Row],[Code2]],'[2]New Machine sheet'!$F$2:$I$64,3,0),0) -> RE J1 | J24: 5 | K24: =IFERROR(VLOOKUP(Table2[[#This Row],[Code3]],'[2]New defect code '!$A$2:$D$129,2,0),0) -> Bore Over size | L24: 01.09.26 | M24: 46266 | N24: 3 | R24: =SUBTOTAL(9,Table2[[#This Row],[1st]:[FQC]]) -> 3 | S24: =IFERROR(VLOOKUP(Table2[[#This Row],[Part No.]],'[2]New Machine sheet'!$G$2:$I$90,3,0),0) -> 135.67 | T24: =Table2[[#This Row],[cost per piece]]*Table2[[#This Row],[Total Rej. qty]] -> 407.01 | U24: =IFERROR(VLOOKUP(Table2[[#This Row],[Non Conformance]],'[2]New defect code '!$B$2:$C$129,2,0),0) -> 3243 | V24: 64 | W24: =IFERROR(VLOOKUP(Table2[[#This Row],[Code4]],'[2]New Reason code'!$A$2:$D$77,2,0),0) -> Wrong correction | X24: =IFERROR(VLOOKUP(Table2[[#This Row],[Reason]],'[2]New Reason code'!$B$2:$D$77,2,0),0) -> Due to operator | Y24: =IFERROR(VLOOKUP(Table2[[#This Row],[Rejection Identified at]],'[2]New Reason code'!$C$2:$D$77,2,0),0) -> infrastructure
A25: 21 | B25: 13 | C25: =IFERROR(VLOOKUP(Table2[[#This Row],[Code]],'[2]New Machine sheet'!$A$1:$D$101,2,0),0) -> 282-13 | D25: =IFERROR(VLOOKUP(Table2[[#This Row],[M/c No]],'[2]New Machine sheet'!$B$1:$D$101,2,0),0) -> Mazak | E25: =IFERROR(VLOOKUP(Table2[[#This Row],[M/c Name]],'[2]New Machine sheet'!$C$1:$D$101,2,0),0) -> Turning | F25: 113 | G25: =IFERROR(VLOOKUP(Table2[[#This Row],[Code2]],'[2]New Machine sheet'!$F$2:$I$64,2,),0) -> 24113 | H25: =IFERROR(VLOOKUP(Table2[[#This Row],[Code2]],'[2]New Machine sheet'!$F$2:$I$64,3,0),0) -> RE J1 | I25: Ravendra | J25: 5 | K25: =IFERROR(VLOOKUP(Table2[[#This Row],[Code3]],'[2]New defect code '!$A$2:$D$129,2,0),0) -> Bore Over size | L25: 01.09.26 | M25: 46266 | N25: 10 | R25: =SUBTOTAL(9,Table2[[#This Row],[1st]:[FQC]]) -> 10 | S25: =IFERROR(VLOOKUP(Table2[[#This Row],[Part No.]],'[2]New Machine sheet'!$G$2:$I$90,3,0),0) -> 90 | T25: =Table2[[#This Row],[cost per piece]]*Table2[[#This Row],[Total Rej. qty]] -> 900 | U25: =IFERROR(VLOOKUP(Table2[[#This Row],[Non Conformance]],'[2]New defect code '!$B$2:$C$129,2,0),0) -> 3243 | V25: 19 | W25: =IFERROR(VLOOKUP(Table2[[#This Row],[Code4]],'[2]New Reason code'!$A$2:$D$77,2,0),0) -> During Rework time | X25: =IFERROR(VLOOKUP(Table2[[#This Row],[Reason]],'[2]New Reason code'!$B$2:$D$77,2,0),0) -> Due to operator | Y25: =IFERROR(VLOOKUP(Table2[[#This Row],[Rejection Identified at]],'[2]New Reason code'!$C$2:$D$77,2,0),0) -> infrastructure
A26: 22 | B26: 2 | C26: =IFERROR(VLOOKUP(Table2[[#This Row],[Code]],'[2]New Machine sheet'!$A$1:$D$101,2,0),0) -> 282-02 | D26: =IFERROR(VLOOKUP(Table2[[#This Row],[M/c No]],'[2]New Machine sheet'!$B$1:$D$101,2,0),0) -> Mazak | E26: =IFERROR(VLOOKUP(Table2[[#This Row],[M/c Name]],'[2]New Machine sheet'!$C$1:$D$101,2,0),0) -> Turning | F26: 75 | G26: =IFERROR(VLOOKUP(Table2[[#This Row],[Code2]],'[2]New Machine sheet'!$F$2:$I$64,2,),0) -> 2475 | H26: =IFERROR(VLOOKUP(Table2[[#This Row],[Code2]],'[2]New Machine sheet'!$F$2:$I$64,3,0),0) -> RE P1 | I26: Varsha | J26: 5 | K26: =IFERROR(VLOOKUP(Table2[[#This Row],[Code3]],'[2]New defect code '!$A$2:$D$129,2,0),0) -> Bore Over size | L26: 01.09.26 | M26: 46266 | N26: 4 | R26: =SUBTOTAL(9,Table2[[#This Row],[1st]:[FQC]]) -> 4 | S26: =IFERROR(VLOOKUP(Table2[[#This Row],[Part No.]],'[2]New Machine sheet'!$G$2:$I$90,3,0),0) -> 138.77 | T26: =Table2[[#This Row],[cost per piece]]*Table2[[#This Row],[Total Rej. qty]] -> 555.08 | U26: =IFERROR(VLOOKUP(Table2[[#This Row],[Non Conformance]],'[2]New defect code '!$B$2:$C$129,2,0),0) -> 3243 | V26: 19 | W26: =IFERROR(VLOOKUP(Table2[[#This Row],[Code4]],'[2]New Reason code'!$A$2:$D$77,2,0),0) -> During Rework time | X26: =IFERROR(VLOOKUP(Table2[[#This Row],[Reason]],'[2]New Reason code'!$B$2:$D$77,2,0),0) -> Due to operator | Y26: =IFERROR(VLOOKUP(Table2[[#This Row],[Rejection Identified at]],'[2]New Reason code'!$C$2:$D$77,2,0),0) -> infrastructure
A27: 23 | B27: 45 | C27: =IFERROR(VLOOKUP(Table2[[#This Row],[Code]],'[2]New Machine sheet'!$A$1:$D$101,2,0),0) -> MURATEC-01 | D27: =IFERROR(VLOOKUP(Table2[[#This Row],[M/c No]],'[2]New Machine sheet'!$B$1:$D$101,2,0),0) -> MURATEC | E27: =IFERROR(VLOOKUP(Table2[[#This Row],[M/c Name]],'[2]New Machine sheet'!$C$1:$D$101,2,0),0) -> turning | F27: 172 | G27: =IFERROR(VLOOKUP(Table2[[#This Row],[Code2]],'[2]New Machine sheet'!$F$2:$I$64,2,),0) -> 24172 | H27: =IFERROR(VLOOKUP(Table2[[#This Row],[Code2]],'[2]New Machine sheet'!$F$2:$I$64,3,0),0) -> RE J1 | I27: Amar | J27: 66 | K27: =IFERROR(VLOOKUP(Table2[[#This Row],[Code3]],'[2]New defect code '!$A$2:$D$129,2,0),0) -> OD Under Size | L27: 01.09.26 | M27: 46266 | N27: 1 | R27: =SUBTOTAL(9,Table2[[#This Row],[1st]:[FQC]]) -> 1 | S27: =IFERROR(VLOOKUP(Table2[[#This Row],[Part No.]],'[2]New Machine sheet'!$G$2:$I$90,3,0),0) -> 348.33 | T27: =Table2[[#This Row],[cost per piece]]*Table2[[#This Row],[Total Rej. qty]] -> 348.33 | U27: =IFERROR(VLOOKUP(Table2[[#This Row],[Non Conformance]],'[2]New defect code '!$B$2:$C$129,2,0),0) -> 3242 | V27: 21 | W27: =IFERROR(VLOOKUP(Table2[[#This Row],[Code4]],'[2]New Reason code'!$A$2:$D$77,2,0),0) -> During setup time | X27: =IFERROR(VLOOKUP(Table2[[#This Row],[Reason]],'[2]New Reason code'!$B$2:$D$77,2,0),0) -> Due to Settup | Y27: =IFERROR(VLOOKUP(Table2[[#This Row],[Rejection Identified at]],'[2]New Reason code'!$C$2:$D$77,2,0),0) -> skill
A28: 24 | B28: 47 | C28: =IFERROR(VLOOKUP(Table2[[#This Row],[Code]],'[2]New Machine sheet'!$A$1:$D$101,2,0),0) -> MURATEC-03 | D28: =IFERROR(VLOOKUP(Table2[[#This Row],[M/c No]],'[2]New Machine sheet'!$B$1:$D$101,2,0),0) -> MURATEC | E28: =IFERROR(VLOOKUP(Table2[[#This Row],[M/c Name]],'[2]New Machine sheet'!$C$1:$D$101,2,0),0) -> turning | F28: 127 | G28: =IFERROR(VLOOKUP(Table2[[#This Row],[Code2]],'[2]New Machine sheet'!$F$2:$I$64,2,),0) -> 24127 | H28: =IFERROR(VLOOKUP(Table2[[#This Row],[Code2]],'[2]New Machine sheet'!$F$2:$I$64,3,0),0) -> RE J1 | I28: Amar | J28: 66 | K28: =IFERROR(VLOOKUP(Table2[[#This Row],[Code3]],'[2]New defect code '!$A$2:$D$129,2,0),0) -> OD Under Size | L28: 01.09.26 | M28: 46266 | N28: 1 | R28: =SUBTOTAL(9,Table2[[#This Row],[1st]:[FQC]]) -> 1 | S28: =IFERROR(VLOOKUP(Table2[[#This Row],[Part No.]],'[2]New Machine sheet'!$G$2:$I$90,3,0),0) -> 262.812 | T28: =Table2[[#This Row],[cost per piece]]*Table2[[#This Row],[Total Rej. qty]] -> 262.812 | U28: =IFERROR(VLOOKUP(Table2[[#This Row],[Non Conformance]],'[2]New defect code '!$B$2:$C$129,2,0),0) -> 3242 | V28: 18 | W28: =IFERROR(VLOOKUP(Table2[[#This Row],[Code4]],'[2]New Reason code'!$A$2:$D$77,2,0),0) -> During insert change | X28: =IFERROR(VLOOKUP(Table2[[#This Row],[Reason]],'[2]New Reason code'!$B$2:$D$77,2,0),0) -> Due to Settup | Y28: =IFERROR(VLOOKUP(Table2[[#This Row],[Rejection Identified at]],'[2]New Reason code'!$C$2:$D$77,2,0),0) -> skill
A29: 25 | B29: 22 | C29: =IFERROR(VLOOKUP(Table2[[#This Row],[Code]],'[2]New Machine sheet'!$A$1:$D$101,2,0),0) -> ACE-02 | D29: =IFERROR(VLOOKUP(Table2[[#This Row],[M/c No]],'[2]New Machine sheet'!$B$1:$D$101,2,0),0) -> Micromatic | E29: =IFERROR(VLOOKUP(Table2[[#This Row],[M/c Name]],'[2]New Machine sheet'!$C$1:$D$101,2,0),0) -> Turning | F29: 178 | G29: =IFERROR(VLOOKUP(Table2[[#This Row],[Code2]],'[2]New Machine sheet'!$F$2:$I$64,2,),0) -> 24178 | H29: =IFERROR(VLOOKUP(Table2[[#This Row],[Code2]],'[2]New Machine sheet'!$F$2:$I$64,3,0),0) -> RE J1 | I29: Devraj | J29: 5 | K29: =IFERROR(VLOOKUP(Table2[[#This Row],[Code3]],'[2]New defect code '!$A$2:$D$129,2,0),0) -> Bore Over size | L29: 01.09.26 | M29: 46266 | N29: 1 | R29: =SUBTOTAL(9,Table2[[#This Row],[1st]:[FQC]]) -> 1 | S29: =IFERROR(VLOOKUP(Table2[[#This Row],[Part No.]],'[2]New Machine sheet'!$G$2:$I$90,3,0),0) -> 70.62 | T29: =Table2[[#This Row],[cost per piece]]*Table2[[#This Row],[Total Rej. qty]] -> 70.62 | U29: =IFERROR(VLOOKUP(Table2[[#This Row],[Non Conformance]],'[2]New defect code '!$B$2:$C$129,2,0),0) -> 3243 | V29: 18 | W29: =IFERROR(VLOOKUP(Table2[[#This Row],[Code4]],'[2]New Reason code'!$A$2:$D$77,2,0),0) -> During insert change | X29: =IFERROR(VLOOKUP(Table2[[#This Row],[Reason]],'[2]New Reason code'!$B$2:$D$77,2,0),0) -> Due to Settup | Y29: =IFERROR(VLOOKUP(Table2[[#This Row],[Rejection Identified at]],'[2]New Reason code'!$C$2:$D$77,2,0),0) -> skill
A30: 26 | B30: 10 | C30: =IFERROR(VLOOKUP(Table2[[#This Row],[Code]],'[2]New Machine sheet'!$A$1:$D$101,2,0),0) -> 282-10 | D30: =IFERROR(VLOOKUP(Table2[[#This Row],[M/c No]],'[2]New Machine sheet'!$B$1:$D$101,2,0),0) -> Mazak | E30: =IFERROR(VLOOKUP(Table2[[#This Row],[M/c Name]],'[2]New Machine sheet'!$C$1:$D$101,2,0),0) -> Turning | F30: 155 | G30: =IFERROR(VLOOKUP(Table2[[#This Row],[Code2]],'[2]New Machine sheet'!$F$2:$I$64,2,),0) -> 24155 | H30: =IFERROR(VLOOKUP(Table2[[#This Row],[Code2]],'[2]New Machine sheet'!$F$2:$I$64,3,0),0) -> RE J1 | I30: Ritu | J30: 5 | K30: =IFERROR(VLOOKUP(Table2[[#This Row],[Code3]],'[2]New defect code '!$A$2:$D$129,2,0),0) -> Bore Over size | L30: 01.09.26 | M30: 46266 | N30: 1 | R30: =SUBTOTAL(9,Table2[[#This Row],[1st]:[FQC]]) -> 1 | S30: =IFERROR(VLOOKUP(Table2[[#This Row],[Part No.]],'[2]New Machine sheet'!$G$2:$I$90,3,0),0) -> 107.67 | T30: =Table2[[#This Row],[cost per piece]]*Table2[[#This Row],[Total Rej. qty]] -> 107.67 | U30: =IFERROR(VLOOKUP(Table2[[#This Row],[Non Conformance]],'[2]New defect code '!$B$2:$C$129,2,0),0) -> 3243 | V30: 18 | W30: =IFERROR(VLOOKUP(Table2[[#This Row],[Code4]],'[2]New Reason code'!$A$2:$D$77,2,0),0) -> During insert change | X30: =IFERROR(VLOOKUP(Table2[[#This Row],[Reason]],'[2]New Reason code'!$B$2:$D$77,2,0),0) -> Due to Settup | Y30: =IFERROR(VLOOKUP(Table2[[#This Row],[Rejection Identified at]],'[2]New Reason code'!$C$2:$D$77,2,0),0) -> skill
A31: 27 | B31: 18 | C31: =IFERROR(VLOOKUP(Table2[[#This Row],[Code]],'[2]New Machine sheet'!$A$1:$D$101,2,0),0) -> 282-18 | D31: =IFERROR(VLOOKUP(Table2[[#This Row],[M/c No]],'[2]New Machine sheet'!$B$1:$D$101,2,0),0) -> Mazak | E31: =IFERROR(VLOOKUP(Table2[[#This Row],[M/c Name]],'[2]New Machine sheet'!$C$1:$D$101,2,0),0) -> Turning | F31: 178 | G31: =IFERROR(VLOOKUP(Table2[[#This Row],[Code2]],'[2]New Machine sheet'!$F$2:$I$64,2,),0) -> 24178 | H31: =IFERROR(VLOOKUP(Table2[[#This Row],[Code2]],'[2]New Machine sheet'!$F$2:$I$64,3,0),0) -> RE J1 | J31: 5 | K31: =IFERROR(VLOOKUP(Table2[[#This Row],[Code3]],'[2]New defect code '!$A$2:$D$129,2,0),0) -> Bore Over size | L31: 01.09.26 | M31: 46266 | N31: 6 | R31: =SUBTOTAL(9,Table2[[#This Row],[1st]:[FQC]]) -> 6 | S31: =IFERROR(VLOOKUP(Table2[[#This Row],[Part No.]],'[2]New Machine sheet'!$G$2:$I$90,3,0),0) -> 70.62 | T31: =Table2[[#This Row],[cost per piece]]*Table2[[#This Row],[Total Rej. qty]] -> 423.72 | U31: =IFERROR(VLOOKUP(Table2[[#This Row],[Non Conformance]],'[2]New defect code '!$B$2:$C$129,2,0),0) -> 3243 | V31: 12 | W31: =IFERROR(VLOOKUP(Table2[[#This Row],[Code4]],'[2]New Reason code'!$A$2:$D$77,2,0),0) -> Double loading | X31: =IFERROR(VLOOKUP(Table2[[#This Row],[Reason]],'[2]New Reason code'!$B$2:$D$77,2,0),0) -> Due to operator | Y31: =IFERROR(VLOOKUP(Table2[[#This Row],[Rejection Identified at]],'[2]New Reason code'!$C$2:$D$77,2,0),0) -> infrastructure
A32: 28 | B32: 5 | C32: =IFERROR(VLOOKUP(Table2[[#This Row],[Code]],'[2]New Machine sheet'!$A$1:$D$101,2,0),0) -> 282-05 | D32: =IFERROR(VLOOKUP(Table2[[#This Row],[M/c No]],'[2]New Machine sheet'!$B$1:$D$101,2,0),0) -> Mazak | E32: =IFERROR(VLOOKUP(Table2[[#This Row],[M/c Name]],'[2]New Machine sheet'!$C$1:$D$101,2,0),0) -> Turning | F32: 119 | G32: =IFERROR(VLOOKUP(Table2[[#This Row],[Code2]],'[2]New Machine sheet'!$F$2:$I$64,2,),0) -> 24119 | H32: =IFERROR(VLOOKUP(Table2[[#This Row],[Code2]],'[2]New Machine sheet'!$F$2:$I$64,3,0),0) -> RE J1 | I32: Suraj | J32: 5 | K32: =IFERROR(VLOOKUP(Table2[[#This Row],[Code3]],'[2]New defect code '!$A$2:$D$129,2,0),0) -> Bore Over size | L32: 01.09.26 | M32: 46266 | O32: 10 | R32: =SUBTOTAL(9,Table2[[#This Row],[1st]:[FQC]]) -> 10 | S32: =IFERROR(VLOOKUP(Table2[[#This Row],[Part No.]],'[2]New Machine sheet'!$G$2:$I$90,3,0),0) -> 103.2 | T32: =Table2[[#This Row],[cost per piece]]*Table2[[#This Row],[Total Rej. qty]] -> 1032 | U32: =IFERROR(VLOOKUP(Table2[[#This Row],[Non Conformance]],'[2]New defect code '!$B$2:$C$129,2,0),0) -> 3243 | V32: 20 | W32: =IFERROR(VLOOKUP(Table2[[#This Row],[Code4]],'[2]New Reason code'!$A$2:$D$77,2,0),0) -> During segrigetion | X32: =IFERROR(VLOOKUP(Table2[[#This Row],[Reason]],'[2]New Reason code'!$B$2:$D$77,2,0),0) -> During segrigetion | Y32: =IFERROR(VLOOKUP(Table2[[#This Row],[Rejection Identified at]],'[2]New Reason code'!$C$2:$D$77,2,0),0) -> Attitude
A33: 29 | B33: 17 | C33: =IFERROR(VLOOKUP(Table2[[#This Row],[Code]],'[2]New Machine sheet'!$A$1:$D$101,2,0),0) -> 282-17 | D33: =IFERROR(VLOOKUP(Table2[[#This Row],[M/c No]],'[2]New Machine sheet'!$B$1:$D$101,2,0),0) -> Mazak | E33: =IFERROR(VLOOKUP(Table2[[#This Row],[M/c Name]],'[2]New Machine sheet'!$C$1:$D$101,2,0),0) -> Turning | F33: 113 | G33: =IFERROR(VLOOKUP(Table2[[#This Row],[Code2]],'[2]New Machine sheet'!$F$2:$I$64,2,),0) -> 24113 | H33: =IFERROR(VLOOKUP(Table2[[#This Row],[Code2]],'[2]New Machine sheet'!$F$2:$I$64,3,0),0) -> RE J1 | I33: Suraj | J33: 5 | K33: =IFERROR(VLOOKUP(Table2[[#This Row],[Code3]],'[2]New defect code '!$A$2:$D$129,2,0),0) -> Bore Over size | L33: 01.09.26 | M33: 46266 | O33: 6 | R33: =SUBTOTAL(9,Table2[[#This Row],[1st]:[FQC]]) -> 6 | S33: =IFERROR(VLOOKUP(Table2[[#This Row],[Part No.]],'[2]New Machine sheet'!$G$2:$I$90,3,0),0) -> 90 | T33: =Table2[[#This Row],[cost per piece]]*Table2[[#This Row],[Total Rej. qty]] -> 540 | U33: =IFERROR(VLOOKUP(Table2[[#This Row],[Non Conformance]],'[2]New defect code '!$B$2:$C$129,2,0),0) -> 3243 | V33: 20 | W33: =IFERROR(VLOOKUP(Table2[[#This Row],[Code4]],'[2]New Reason code'!$A$2:$D$77,2,0),0) -> During segrigetion | X33: =IFERROR(VLOOKUP(Table2[[#This Row],[Reason]],'[2]New Reason code'!$B$2:$D$77,2,0),0) -> During segrigetion | Y33: =IFERROR(VLOOKUP(Table2[[#This Row],[Rejection Identified at]],'[2]New Reason code'!$C$2:$D$77,2,0),0) -> Attitude
A34: 30 | B34: 8 | C34: =IFERROR(VLOOKUP(Table2[[#This Row],[Code]],'[2]New Machine sheet'!$A$1:$D$101,2,0),0) -> 282-08 | D34: =IFERROR(VLOOKUP(Table2[[#This Row],[M/c No]],'[2]New Machine sheet'!$B$1:$D$101,2,0),0) -> Mazak | E34: =IFERROR(VLOOKUP(Table2[[#This Row],[M/c Name]],'[2]New Machine sheet'!$C$1:$D$101,2,0),0) -> Turning | F34: 117 | G34: =IFERROR(VLOOKUP(Table2[[#This Row],[Code2]],'[2]New Machine sheet'!$F$2:$I$64,2,),0) -> 24117 | H34: =IFERROR(VLOOKUP(Table2[[#This Row],[Code2]],'[2]New Machine sheet'!$F$2:$I$64,3,0),0) -> RE J1 | I34: Rohit | J34: 5 | K34: =IFERROR(VLOOKUP(Table2[[#This Row],[Code3]],'[2]New defect code '!$A$2:$D$129,2,0),0) -> Bore Over size | L34: 01.09.26 | M34: 46266 | O34: 10 | R34: =SUBTOTAL(9,Table2[[#This Row],[1st]:[FQC]]) -> 10 | S34: =IFERROR(VLOOKUP(Table2[[#This Row],[Part No.]],'[2]New Machine sheet'!$G$2:$I$90,3,0),0) -> 111.97 | T34: =Table2[[#This Row],[cost per piece]]*Table2[[#This Row],[Total Rej. qty]] -> 1119.7 | U34: =IFERROR(VLOOKUP(Table2[[#This Row],[Non Conformance]],'[2]New defect code '!$B$2:$C$129,2,0),0) -> 3243 | V34: 20 | W34: =IFERROR(VLOOKUP(Table2[[#This Row],[Code4]],'[2]New Reason code'!$A$2:$D$77,2,0),0) -> During segrigetion | X34: =IFERROR(VLOOKUP(Table2[[#This Row],[Reason]],'[2]New Reason code'!$B$2:$D$77,2,0),0) -> During segrigetion | Y34: =IFERROR(VLOOKUP(Table2[[#This Row],[Rejection Identified at]],'[2]New Reason code'!$C$2:$D$77,2,0),0) -> Attitude
A35: 31 | B35: 20 | C35: =IFERROR(VLOOKUP(Table2[[#This Row],[Code]],'[2]New Machine sheet'!$A$1:$D$101,2,0),0) -> 282-20 | D35: =IFERROR(VLOOKUP(Table2[[#This Row],[M/c No]],'[2]New Machine sheet'!$B$1:$D$101,2,0),0) -> Mazak | E35: =IFERROR(VLOOKUP(Table2[[#This Row],[M/c Name]],'[2]New Machine sheet'!$C$1:$D$101,2,0),0) -> Turning | F35: 115 | G35: =IFERROR(VLOOKUP(Table2[[#This Row],[Code2]],'[2]New Machine sheet'!$F$2:$I$64,2,),0) -> 24115 | H35: =IFERROR(VLOOKUP(Table2[[#This Row],[Code2]],'[2]New Machine sheet'!$F$2:$I$64,3,0),0) -> RE J1 | I35: Rajesh | J35: 5 | K35: =IFERROR(VLOOKUP(Table2[[#This Row],[Code3]],'[2]New defect code '!$A$2:$D$129,2,0),0) -> Bore Over size | L35: 01.09.26 | M35: 46266 | O35: 3 | R35: =SUBTOTAL(9,Table2[[#This Row],[1st]:[FQC]]) -> 3 | S35: =IFERROR(VLOOKUP(Table2[[#This Row],[Part No.]],'[2]New Machine sheet'!$G$2:$I$90,3,0),0) -> 66.9 | T35: =Table2[[#This Row],[cost per piece]]*Table2[[#This Row],[Total Rej. qty]] -> 200.7 | U35: =IFERROR(VLOOKUP(Table2[[#This Row],[Non Conformance]],'[2]New defect code '!$B$2:$C$129,2,0),0) -> 3243 | V35: 20 | W35: =IFERROR(VLOOKUP(Table2[[#This Row],[Code4]],'[2]New Reason code'!$A$2:$D$77,2,0),0) -> During segrigetion | X35: =IFERROR(VLOOKUP(Table2[[#This Row],[Reason]],'[2]New Reason code'!$B$2:$D$77,2,0),0) -> During segrigetion | Y35: =IFERROR(VLOOKUP(Table2[[#This Row],[Rejection Identified at]],'[2]New Reason code'!$C$2:$D$77,2,0),0) -> Attitude
A36: 32 | B36: 41 | C36: =IFERROR(VLOOKUP(Table2[[#This Row],[Code]],'[2]New Machine sheet'!$A$1:$D$101,2,0),0) -> 252-03 | D36: =IFERROR(VLOOKUP(Table2[[#This Row],[M/c No]],'[2]New Machine sheet'!$B$1:$D$101,2,0),0) -> VMC | E36: =IFERROR(VLOOKUP(Table2[[#This Row],[M/c Name]],'[2]New Machine sheet'!$C$1:$D$101,2,0),0) -> VMC | F36: 155 | G36: =IFERROR(VLOOKUP(Table2[[#This Row],[Code2]],'[2]New Machine sheet'!$F$2:$I$64,2,),0) -> 24155 | H36: =IFERROR(VLOOKUP(Table2[[#This Row],[Code2]],'[2]New Machine sheet'!$F$2:$I$64,3,0),0) -> RE J1 | I36: Vijay | J36: 32 | K36: =IFERROR(VLOOKUP(Table2[[#This Row],[Code3]],'[2]New defect code '!$A$2:$D$129,2,0),0) -> Double Dot Punching | L36: 01.09.26 | M36: 46266 | O36: 2 | R36: =SUBTOTAL(9,Table2[[#This Row],[1st]:[FQC]]) -> 2 | S36: =IFERROR(VLOOKUP(Table2[[#This Row],[Part No.]],'[2]New Machine sheet'!$G$2:$I$90,3,0),0) -> 107.67 | T36: =Table2[[#This Row],[cost per piece]]*Table2[[#This Row],[Total Rej. qty]] -> 215.34 | U36: =IFERROR(VLOOKUP(Table2[[#This Row],[Non Conformance]],'[2]New defect code '!$B$2:$C$129,2,0),0) -> 0 | V36: 66 | W36: =IFERROR(VLOOKUP(Table2[[#This Row],[Code4]],'[2]New Reason code'!$A$2:$D$77,2,0),0) -> Wrong Loading | X36: =IFERROR(VLOOKUP(Table2[[#This Row],[Reason]],'[2]New Reason code'!$B$2:$D$77,2,0),0) -> Due to operator | Y36: =IFERROR(VLOOKUP(Table2[[#This Row],[Rejection Identified at]],'[2]New Reason code'!$C$2:$D$77,2,0),0) -> infrastructure
